Workbook

Sheet Summary
A1: Top Category | B1: Products | C1: Share of Catalog | D1: FORTPRO Brand | E1: Other Brands | F1: Not Tagged | G1: FORTPRO Share
A2: Lighting | B2: =COUNTIF(Products!$E$2:$E$3170,A2) -> 376 | C2: =IF($B$18=0,0,B2/$B$18) -> 0.11864942 | D2: =COUNTIFS(Products!$E$2:$E$3170,A2,Products!$D$2:$D$3170,"FORTPRO") -> 376 | E2: =B2-D2-F2 -> 0 | F2: =COUNTIFS(Products!$E$2:$E$3170,A2,Products!$D$2:$D$3170,"Not tagged") -> 0 | G2: =IF(B2=0,0,D2/B2) -> 1
A3: Exterior Parts | B3: =COUNTIF(Products!$E$2:$E$3170,A3) -> 136 | C3: =IF($B$18=0,0,B3/$B$18) -> 0.042915746 | D3: =COUNTIFS(Products!$E$2:$E$3170,A3,Products!$D$2:$D$3170,"FORTPRO") -> 123 | E3: =B3-D3-F3 -> 0 | F3: =COUNTIFS(Products!$E$2:$E$3170,A3,Products!$D$2:$D$3170,"Not tagged") -> 13 | G3: =IF(B3=0,0,D3/B3) -> 0.90441176
A4: Interior Parts | B4: =COUNTIF(Products!$E$2:$E$3170,A4) -> 99 | C4: =IF($B$18=0,0,B4/$B$18) -> 0.031240139 | D4: =COUNTIFS(Products!$E$2:$E$3170,A4,Products!$D$2:$D$3170,"FORTPRO") -> 2 | E4: =B4-D4-F4 -> 0 | F4: =COUNTIFS(Products!$E$2:$E$3170,A4,Products!$D$2:$D$3170,"Not tagged") -> 97 | G4: =IF(B4=0,0,D4/B4) -> 0.02020202
A5: Accessories | B5: =COUNTIF(Products!$E$2:$E$3170,A5) -> 80 | C5: =IF($B$18=0,0,B5/$B$18) -> 0.025244557 | D5: =COUNTIFS(Products!$E$2:$E$3170,A5,Products!$D$2:$D$3170,"FORTPRO") -> 77 | E5: =B5-D5-F5 -> 0 | F5: =COUNTIFS(Products!$E$2:$E$3170,A5,Products!$D$2:$D$3170,"Not tagged") -> 3 | G5: =IF(B5=0,0,D5/B5) -> 0.9625
A6: Brake System | B6: =COUNTIF(Products!$E$2:$E$3170,A6) -> 575 | C6: =IF($B$18=0,0,B6/$B$18) -> 0.18144525 | D6: =COUNTIFS(Products!$E$2:$E$3170,A6,Products!$D$2:$D$3170,"FORTPRO") -> 461 | E6: =B6-D6-F6 -> 5 | F6: =COUNTIFS(Products!$E$2:$E$3170,A6,Products!$D$2:$D$3170,"Not tagged") -> 109 | G6: =IF(B6=0,0,D6/B6) -> 0.80173913
A7: Engine Components | B7: =COUNTIF(Products!$E$2:$E$3170,A7) -> 484 | C7: =IF($B$18=0,0,B7/$B$18) -> 0.15272957 | D7: =COUNTIFS(Products!$E$2:$E$3170,A7,Products!$D$2:$D$3170,"FORTPRO") -> 386 | E7: =B7-D7-F7 -> 11 | F7: =COUNTIFS(Products!$E$2:$E$3170,A7,Products!$D$2:$D$3170,"Not tagged") -> 87 | G7: =IF(B7=0,0,D7/B7) -> 0.79752066
A8: Electrical | B8: =COUNTIF(Products!$E$2:$E$3170,A8) -> 220 | C8: =IF($B$18=0,0,B8/$B$18) -> 0.069422531 | D8: =COUNTIFS(Products!$E$2:$E$3170,A8,Products!$D$2:$D$3170,"FORTPRO") -> 107 | E8: =B8-D8-F8 -> 1 | F8: =COUNTIFS(Products!$E$2:$E$3170,A8,Products!$D$2:$D$3170,"Not tagged") -> 112 | G8: =IF(B8=0,0,D8/B8) -> 0.48636364
A9: Exhaust System | B9: =COUNTIF(Products!$E$2:$E$3170,A9) -> 83 | C9: =IF($B$18=0,0,B9/$B$18) -> 0.026191228 | D9: =COUNTIFS(Products!$E$2:$E$3170,A9,Products!$D$2:$D$3170,"FORTPRO") -> 82 | E9: =B9-D9-F9 -> 0 | F9: =COUNTIFS(Products!$E$2:$E$3170,A9,Products!$D$2:$D$3170,"Not tagged") -> 1 | G9: =IF(B9=0,0,D9/B9) -> 0.98795181
A10: Suspension | B10: =COUNTIF(Products!$E$2:$E$3170,A10) -> 436 | C10: =IF($B$18=0,0,B10/$B$18) -> 0.13758283 | D10: =COUNTIFS(Products!$E$2:$E$3170,A10,Products!$D$2:$D$3170,"FORTPRO") -> 335 | E10: =B10-D10-F10 -> 6 | F10: =COUNTIFS(Products!$E$2:$E$3170,A10,Products!$D$2:$D$3170,"Not tagged") -> 95 | G10: =IF(B10=0,0,D10/B10) -> 0.76834862
A11: Cabin, Engine & Hood Components | B11: =COUNTIF(Products!$E$2:$E$3170,A11) -> 72 | C11: =IF($B$18=0,0,B11/$B$18) -> 0.022720101 | D11: =COUNTIFS(Products!$E$2:$E$3170,A11,Products!$D$2:$D$3170,"FORTPRO") -> 69 | E11: =B11-D11-F11 -> 0 | F11: =COUNTIFS(Products!$E$2:$E$3170,A11,Products!$D$2:$D$3170,"Not tagged") -> 3 | G11: =IF(B11=0,0,D11/B11) -> 0.95833333
A12: Driveline & Axles | B12: =COUNTIF(Products!$E$2:$E$3170,A12) -> 370 | C12: =IF($B$18=0,0,B12/$B$18) -> 0.11675607 | D12: =COUNTIFS(Products!$E$2:$E$3170,A12,Products!$D$2:$D$3170,"FORTPRO") -> 256 | E12: =B12-D12-F12 -> 65 | F12: =COUNTIFS(Products!$E$2:$E$3170,A12,Products!$D$2:$D$3170,"Not tagged") -> 49 | G12: =IF(B12=0,0,D12/B12) -> 0.69189189
A13: Steerings | B13: =COUNTIF(Products!$E$2:$E$3170,A13) -> 71 | C13: =IF($B$18=0,0,B13/$B$18) -> 0.022404544 | D13: =COUNTIFS(Products!$E$2:$E$3170,A13,Products!$D$2:$D$3170,"FORTPRO") -> 71 | E13: =B13-D13-F13 -> 0 | F13: =COUNTIFS(Products!$E$2:$E$3170,A13,Products!$D$2:$D$3170,"Not tagged") -> 0 | G13: =IF(B13=0,0,D13/B13) -> 1
... A17: Brand page only | B17: =COUNTIF(Products!$E$2:$E$3170,A17) -> 107 | C17: =IF($B$18=0,0,B17/$B$18) -> 0.033764595 | D17: =COUNTIFS(Products!$E$2:$E$3170,A17,Products!$D$2:$D$3170,"FORTPRO") -> 95 | E17: =B17-D17-F17 -> 12 | F17: =COUNTIFS(Products!$E$2:$E$3170,A17,Products!$D$2:$D$3170,"Not tagged") -> 0 | G17: =IF(B17=0,0,D17/B17) -> 0.88785047
A18: Total | B18: =SUM(B2:B17) -> 3169 | C18: =SUM(C2:C17) -> 1 | D18: =SUM(D2:D17) -> 2469 | E18: =SUM(E2:E17) -> 131 | F18: =SUM(F2:F17) -> 569 | G18: =IF(B18=0,0,D18/B18) -> 0.77911013
A20: Top Category uses each product's primary category. Products listed in two top categories count once.

Sheet Brands
A1: Brand | B1: Products | C1: Share of Catalog | D1: Manufacturer Page
A2: FORTPRO | B2: =COUNTIF(Products!$D$2:$D$3170,A2) -> 2469 | C2: =B2/$B$12 -> 0.77911013 | D2: https://www.fortpro.com/fortpro
A3: Spicer | B3: =COUNTIF(Products!$D$2:$D$3170,A3) -> 43 | C3: =B3/$B$12 -> 0.013568949 | D3: https://www.fortpro.com/spicer
A4: Lucas Oil | B4: =COUNTIF(Products!$D$2:$D$3170,A4) -> 34 | C4: =B4/$B$12 -> 0.010728937 | D4: https://www.fortpro.com/lucas-oil
A5: Road Choice | B5: =COUNTIF(Products!$D$2:$D$3170,A5) -> 22 | C5: =B5/$B$12 -> 0.0069422531 | D5: https://www.fortpro.com/roadchoice
A6: Mahle | B6: =COUNTIF(Products!$D$2:$D$3170,A6) -> 15 | C6: =B6/$B$12 -> 0.0047333544 | D6: https://www.fortpro.com/mahle
A7: Bendix | B7: =COUNTIF(Products!$D$2:$D$3170,A7) -> 11 | C7: =B7/$B$12 -> 0.0034711265 | D7: https://www.fortpro.com/bendix
A8: SAF-HOLLAND | B8: =COUNTIF(Products!$D$2:$D$3170,A8) -> 6 | C8: =B8/$B$12 -> 0.0018933417 | D8: https://www.fortpro.com/saf-holland
A9: Donaldson | B9: =COUNTIF(Products!$D$2:$D$3170,A9) -> 0 | C9: =B9/$B$12 -> 0 | D9: https://www.fortpro.com/donaldson
A10: NTN | B10: =COUNTIF(Products!$D$2:$D$3170,A10) -> 0 | C10: =B10/$B$12 -> 0 | D10: https://www.fortpro.com/ntn
A11: Not tagged | B11: =COUNTIF(Products!$D$2:$D$3170,A11) -> 569 | C11: =B11/$B$12 -> 0.17955191
A12: Total | B12: =SUM(B2:B11) -> 3169 | C12: =SUM(C2:C11) -> 1
A14: Donaldson and NTN have manufacturer pages on the site but list 0 products as of Oct 10, 2026.

Sheet README
A1: FORTPRO Product Catalog Index
A2: Purpose | B2: Record of every product listed on fortpro.com, for the Group 5 capstone (ISM6429) with World Truck Parts, LLC dba FORTPRO.
A3: Source | B3: Public website https://www.fortpro.com, crawled Oct 10, 2026 by Claude through Chrome. Every category page (all pages, 60 products per page) and every manufacturer page was read.
A4: Coverage | B4: 3,169 unique products across 15 top-level categories and 185 category pages, plus 9 manufacturer pages.
A5: Not included | B5: Prices, stock levels, and product descriptions. Prices sit behind the B2B login. Stock per warehouse is only visible to logged-in accounts.
A6: Brand field | B6: Taken from the site's manufacturer pages. "Not tagged" means the product is not listed under any manufacturer page (569 products). Many of these use FORTPRO-style SKUs, so the true FORTPRO share is likely higher. Confirm with Jose or Daniel.
A7: Category field | B7: Products can sit in more than one category. All Categories lists every lowest-level category a product appears in, separated by " | ". Primary Category is the first one listed. "Brand page only" means the product appears on a manufacturer page but in no category (107 products).
A8: Site vs record counts | B8: The Categories tab compares the count the site showed during the crawl (blue, hardcoded) with a live formula count from the Products tab. A mismatch flags a category to recheck.
A9: Data quality notes | B9: Product names are copied as the site shows them, including OEM cross-reference numbers (for example "replaces Bendix 286370") and site typos such as "Transmision" and "Componenes". Several category pages exist but list 0 products, for example Toolboxes, Engine Sensors, and Torque Rods & Bushings.
A10: How to use | B10: Filter the Products tab by Brand, Top Category, or Primary Category. Summary and Brands tabs update automatically from the Products tab.
A11: Caveat | B11: The public site is the online catalog, not the SAP item master. SAP likely holds more SKUs, including inactive and non-web items. Use this record to prepare for discovery, not as the analysis dataset.

Sheet Products
A1: Product ID | B1: SKU | C1: Product Name | D1: Brand | E1: Top Category | F1: Subcategory | G1: Primary Category | H1: All Categories | I1: Category Count | J1: Product URL
A2: 3720 | B2: 745-289714N | C2: Air Brake Quick Release Valve | D2: Bendix | E2: Brake System | F2: Air Brake System | G2: Air Brake Valves | H2: Brake System > Air Brake System > Air Brake Valves | I2: 1 | J2: https://www.fortpro.com/air-brake-quick-release-valve
A3: 3704 | B3: 745-OR289714X | C3: CORELESS VALVE | D3: Bendix | E3: Brake System | F3: Air Brake System | G3: Air Brake Valves | H3: Brake System > Air Brake System > Air Brake Valves | I3: 1 | J3: https://www.fortpro.com/coreless-valve
A4: 3703 | B4: 745-K297277 | C4: BRAKE PAD KIT | D4: Bendix | E4: Brake System | F4: Air Brake System | G4: Air Disc Brake Pad Kits | H4: Brake System > Air Brake System > Air Disc Brake Pad Kits | I4: 1 | J4: https://www.fortpro.com/brake-pad-kit
A5: 3111 | B5: 745-NT3030ELSWC | C5: Bendix Brake Chamber 3030 Long Stroke W CLEVIS | D5: Bendix | E5: Brake System | F5: Drum Brake System | G5: Brake Chambers | H5: Brake System > Drum Brake System > Brake Chambers | I5: 1 | J5: https://www.fortpro.com/bendix-brake-chamber-3030-long-stroke-w-clevis
A6: 1619 | B6: 745-NT3030STD78DS | C6: Bendix Brake Chamber 3030 Combo W/O CLEVIS | D6: Bendix | E6: Brake System | F6: Drum Brake System | G6: Brake Chambers | H6: Brake System > Drum Brake System > Brake Chambers | I6: 1 | J6: https://www.fortpro.com/bendix-brake-chamber-3030-combo-wo-clevis
A7: 3721 | B7: 745-229859N | C7: QUICK RELEASE VALVE | D7: Bendix | E7: Brand page only | I7: 0 | J7: https://www.fortpro.com/quick-release-valve
A8: 3702 | B8: 745-K070951 | C8: ATR – 6 TRACTION RELAY | D8: Bendix | E8: Brand page only | I8: 0 | J8: https://www.fortpro.com/atr-6-traction-relay
A9: 3522 | B9: 745-NT3030ELS80DS | C9: Bendix Brake Chamber 3030 Combo Long Stroke W/O CLEVIS | D9: Bendix | E9: Brand page only | I9: 0 | J9: https://www.fortpro.com/bendix-brake-chamber-3030-combo-long-stroke-wo-clevis
A10: 3519 | B10: 745-NT3030STD120DS | C10: Bendix 3030 Standard Stroke S-Cam Spring Brake Chamber with 12" Push Rod | D10: Bendix | E10: Brand page only | I10: 0 | J10: https://www.fortpro.com/bendix-3030-standard-stroke-s-cam-spring-brake-chamber-with-12-push-rod
A11: 3626 | B11: 745-NT3030STDWCDS | C11: BENDIX 30/30 BRAKE CHAMBER LONG STROKE WITH WELDED CLEVIS (2" STROKE) | D11: Bendix | E11: Brand page only | I11: 0 | J11: https://www.fortpro.com/bendix-3030-brake-chamber-long-stroke-with-welded-clevis-2-stroke
A12: 3705 | B12: 745-K239423 | C12: K181267 Bendix ABS sensor With 69" Cable Length | D12: Bendix | E12: Electrical | F12: Sensors | G12: Sensors | H12: Electrical > Sensors | I12: 1 | J12: https://www.fortpro.com/k181267-bendix-abs-sensor-with-69-cable-length
A13: 668 | B13: F224762 | C13: AIR HORN RECTANGULAR | D13: FORTPRO | E13: Accessories | F13: Air Horns | G13: Air Horns | H13: Accessories > Air Horns | I13: 1 | J13: https://www.fortpro.com/air-horn-rectangular
A14: 1445 | B14: F224766 | C14: AIR HORN ROUND | D14: FORTPRO | E14: Accessories | F14: Air Horns | G14: Air Horns | H14: Accessories > Air Horns | I14: 1 | J14: https://www.fortpro.com/air-horn-round
A15: 2061 | B15: F224767 | C15: 2 BELL AIR HORN SMALL | D15: FORTPRO | E15: Accessories | F15: Air Horns | G15: Air Horns | H15: Accessories > Air Horns | I15: 1 | J15: https://www.fortpro.com/2-bell-air-horn-small
A16: 2077 | B16: F224768 | C16: 3 BELL AIR HORN | D16: FORTPRO | E16: Accessories | F16: Air Horns | G16: Air Horns | H16: Accessories > Air Horns | I16: 1 | J16: https://www.fortpro.com/3-bell-air-horn
A17: 2167 | B17: F224899 | C17: DVP - VALVE AIR CONTROL(HV-3) F86RD16A | D17: FORTPRO | E17: Accessories | F17: Air Horns | G17: Air Horns | H17: Accessories > Air Horns | I17: 1 | J17: https://www.fortpro.com/dvp-valve-air-controlhv-3-f86rd16a
A18: 2169 | B18: F224900 | C18: DVP - VALVE AIR CONTROL (HV-3) F86RD13A 228928 | D18: FORTPRO | E18: Accessories | F18: Air Horns | G18: Air Horns | H18: Accessories > Air Horns | I18: 1 | J18: https://www.fortpro.com/dvp-valve-air-control-hv-3-f86rd13a-228928
A19: 3454 | B19: F224901 | C19: 20QE29317 VALVE AIR HORN CONTROL PLASTIC | D19: FORTPRO | E19: Accessories | F19: Air Horns | G19: Air Horns | H19: Accessories > Air Horns | I19: 1 | J19: https://www.fortpro.com/20qe29317-valve-air-horn-control-plastic
A20: 2579 | B20: F245522 | C20: MUD FLAP HANGER CHROME 45 DEGREE ANGLE 2-1/2" SPACING BETWEEN BOLTS. SOLD BY PAIR | D20: FORTPRO | E20: Accessories | F20: Mud Flaps & Hangers | G20: Mud Flaps & Hangers | H20: Accessories > Mud Flaps & Hangers | I20: 1 | J20: https://www.fortpro.com/mud-flap-hanger-chrome-45-degree-angle-2-12-spacing-between-bolts-sold-by-pair
A21: 2659 | B21: F245691 | C21: MUD FLAP HANGER STRAIGHT 2-1/2" SPACING BETWEEN BOLT. CHROME SOLD BY PAIR | D21: FORTPRO | E21: Accessories | F21: Mud Flaps & Hangers | G21: Mud Flaps & Hangers | H21: Accessories > Mud Flaps & Hangers | I21: 1 | J21: https://www.fortpro.com/mud-flap-hanger-straight-2-12-spacing-between-bolt-chrome-sold-by-pair
A22: 2656 | B22: F245692 | C22: REPLACE F247692 / "MUD FLAP PLAIN BLACK 24""X30" | D22: FORTPRO | E22: Accessories | F22: Mud Flaps & Hangers | G22: Mud Flaps & Hangers | H22: Accessories > Mud Flaps & Hangers | I22: 1 | J22: https://www.fortpro.com/replace-f247692-mud-flap-plain-black-24x30
A23: 2646 | B23: F245693E | C23: MUD FLAP BLACK WITH WHITE LETTERING 24"X30" | D23: FORTPRO | E23: Accessories | F23: Mud Flaps & Hangers | G23: Mud Flaps & Hangers | H23: Accessories > Mud Flaps & Hangers | I23: 1 | J23: https://www.fortpro.com/mud-flap-black-with-white-lettering-24x30
... A550: 751 | B550: F225066 | C550: FAS1138 AUTOMATIC SLACK ADJUSTER 1-1/4IN - 24 TEETH 5.5" | D550: FORTPRO | E550: Brake System | F550: Drum Brake System | G550: Slack Adjusters | H550: Brake System > Drum Brake System > Slack Adjusters | I550: 1 | J550: https://www.fortpro.com/fas1138-automatic-slack-adjuster-1-14in-24-teeth-55
A551: 3206 | B551: F010016-001 | C551: F579GB41C GASKET,OIL PAN E6 (1 pcs Pack) | D551: FORTPRO | E551: Brand page only | I551: 0 | J551: https://www.fortpro.com/f579gb41c-gasketoil-pan-e6-1-pcs-pack
A552: 3642 | B552: F010049 | C552: Water Pump Volvo 20431135, 20713787 | D552: FORTPRO | E552: Brand page only | I552: 0 | J552: https://www.fortpro.com/water-pump-volvo-20431135-20713787
A553: 3641 | B553: F010292 | C553: FRONT ENGINE MOUNT E7, E-Tech, ASET 20503552 | D553: FORTPRO | E553: Brand page only | I553: 0 | J553: https://www.fortpro.com/front-engine-mount-e7-e-tech-aset-20503552
A554: 3538 | B554: F010360-002 | C554: Overhaul Kit E7 E-Tech Long Life(S11) FORTPRO | D554: FORTPRO | E554: Brand page only | I554: 0 | J554: https://www.fortpro.com/overhaul-kit-e7-e-tech-long-lifes11-fortpro
A555: 3645 | B555: F021090 | C555: Water Pump Cummins ISX 3684449, 3687130 | D555: FORTPRO | E555: Brand page only | I555: 0 | J555: https://www.fortpro.com/water-pump-cummins-isx-3684449-3687130
A556: 3643 | B556: F021186 | C556: Water Pump Cummins ISX 4089908 | D556: FORTPRO | E556: Brand page only | I556: 0 | J556: https://www.fortpro.com/water-pump-cummins-isx-4089908
A557: 3644 | B557: F021188 | C557: Water Pump Cummins ISX15 4089911 | D557: FORTPRO | E557: Brand page only | I557: 0 | J557: https://www.fortpro.com/water-pump-cummins-isx15-4089911
A558: 3690 | B558: F051813 | C558: S42262, 23537529 PISTON RING SET | D558: FORTPRO | E558: Brand page only | I558: 0 | J558: https://www.fortpro.com/s42262-23537529-piston-ring-set
A559: 3646 | B559: F051867 | C559: Water Pump DD13 DD15 DD16 EA4722000401, EA4722000101 | D559: FORTPRO | E559: Brand page only | I559: 0 | J559: https://www.fortpro.com/water-pump-dd13-dd15-dd16-ea4722000401-ea4722000101
A560: 3684 | B560: F051886 | C560: MS2310P, 8929670 MAIN BEARING SET | D560: FORTPRO | E560: Brand page only | I560: 0 | J560: https://www.fortpro.com/ms2310p-8929670-main-bearing-set
A561: 3685 | B561: F051887 | C561: MS2346P, 23535010 MAIN BEARING SET | D561: FORTPRO | E561: Brand page only | I561: 0 | J561: https://www.fortpro.com/ms2346p-23535010-main-bearing-set
A562: 3686 | B562: F051896 | C562: TW696S, 23530554 THRUST WASHER | D562: FORTPRO | E562: Brand page only | I562: 0 | J562: https://www.fortpro.com/tw696s-23530554-thrust-washer
... A645: 3622 | B645: F327386 | C645: Motor Mount Bushing D29691285, K0662423, K066404 | D645: FORTPRO | E645: Brand page only | I645: 0 | J645: https://www.fortpro.com/motor-mount-bushing-d29691285-k0662423-k066404
A646: 2621 | B646: F245634 | C646: HOOD LATCH LH 3QM313M | D646: FORTPRO | E646: Cabin, Engine & Hood Components | F646: Cabin & Hood Components | G646: Cabin & Hood Components | H646: Cabin, Engine & Hood Components > Cabin & Hood Components | I646: 1 | J646: https://www.fortpro.com/hood-latch-lh-3qm313m
A647: 1026 | B647: F245635 | C647: HOOD LATCH, RH 3QM313M2 / 3QM313M | D647: FORTPRO | E647: Cabin, Engine & Hood Components | F647: Cabin & Hood Components | G647: Cabin & Hood Components | H647: Cabin, Engine & Hood Components > Cabin & Hood Components | I647: 1 | J647: https://www.fortpro.com/hood-latch-rh-3qm313m2-3qm313m
A648: 1286 | B648: F306960 | C648: HOOD LATCH 16899930C91 | D648: FORTPRO | E648: Cabin, Engine & Hood Components | F648: Cabin & Hood Components | G648: Cabin & Hood Components | H648: Cabin, Engine & Hood Components > Cabin & Hood Components | I648: 1 | J648: https://www.fortpro.com/hood-latch-16899930c91
...

Sheet Categories
A1: Category Path | B1: Level | C1: Top Category | D1: Category | E1: Site Count (crawl) | F1: Count in Record | G1: Match | H1: Category URL
A2: Lighting | B2: 1 | C2: Lighting | D2: Lighting | E2: 376 | F2: =SUMPRODUCT(--ISNUMBER(SEARCH("| "&A2,"| "&Products!$H$2:$H$3170))) -> 376 | G2: =IF(E2=F2,"OK","Check") -> OK | H2: https://www.fortpro.com/semi-trucks-driving-lights-and-fog-lights
A3: Lighting > Headlights | B3: 2 | C3: Lighting | D3: Headlights | E3: 104 | F3: =SUMPRODUCT(--ISNUMBER(SEARCH("| "&A3,"| "&Products!$H$2:$H$3170))) -> 104 | G3: =IF(E3=F3,"OK","Check") -> OK | H3: https://www.fortpro.com/semi-trucks-headlights
A4: Lighting > Fog Lights | B4: 2 | C4: Lighting | D4: Fog Lights | E4: 24 | F4: =SUMPRODUCT(--ISNUMBER(SEARCH("| "&A4,"| "&Products!$H$2:$H$3170))) -> 24 | G4: =IF(E4=F4,"OK","Check") -> OK | H4: https://www.fortpro.com/semi-trucks-fog-lights
A5: Lighting > LED Lights | B5: 2 | C5: Lighting | D5: LED Lights | E5: 188 | F5: =SUMPRODUCT(--ISNUMBER(SEARCH("| "&A5,"| "&Products!$H$2:$H$3170))) -> 188 | G5: =IF(E5=F5,"OK","Check") -> OK | H5: https://www.fortpro.com/semi-trucks-led-lights
A6: Lighting > Incandescent Lights | B6: 2 | C6: Lighting | D6: Incandescent Lights | E6: 27 | F6: =SUMPRODUCT(--ISNUMBER(SEARCH("| "&A6,"| "&Products!$H$2:$H$3170))) -> 27 | G6: =IF(E6=F6,"OK","Check") -> OK | H6: https://www.fortpro.com/semi-trucks-incandescent-lights
A7: Lighting > Mounting Accessories | B7: 2 | C7: Lighting | D7: Mounting Accessories | E7: 32 | F7: =SUMPRODUCT(--ISNUMBER(SEARCH("| "&A7,"| "&Products!$H$2:$H$3170))) -> 32 | G7: =IF(E7=F7,"OK","Check") -> OK | H7: https://www.fortpro.com/semi-trucks-lights-mounting-accessories
A8: Lighting > Reflective Safety Tape | B8: 2 | C8: Lighting | D8: Reflective Safety Tape | E8: 1 | F8: =SUMPRODUCT(--ISNUMBER(SEARCH("| "&A8,"| "&Products!$H$2:$H$3170))) -> 1 | G8: =IF(E8=F8,"OK","Check") -> OK | H8: https://www.fortpro.com/reflective-safety-tape
A9: Exterior Parts | B9: 1 | C9: Exterior Parts | D9: Exterior Parts | E9: 136 | F9: =SUMPRODUCT(--ISNUMBER(SEARCH("| "&A9,"| "&Products!$H$2:$H$3170))) -> 136 | G9: =IF(E9=F9,"OK","Check") -> OK | H9: https://www.fortpro.com/semi-trucks-exterior-parts
A10: Exterior Parts > Bumpers | B10: 2 | C10: Exterior Parts | D10: Bumpers | E10: 15 | F10: =SUMPRODUCT(--ISNUMBER(SEARCH("| "&A10,"| "&Products!$H$2:$H$3170))) -> 15 | G10: =IF(E10=F10,"OK","Check") -> OK | H10: https://www.fortpro.com/semi-trucks-bumpers
A11: Exterior Parts > Grilles | B11: 2 | C11: Exterior Parts | D11: Grilles | E11: 39 | F11: =SUMPRODUCT(--ISNUMBER(SEARCH("| "&A11,"| "&Products!$H$2:$H$3170))) -> 39 | G11: =IF(E11=F11,"OK","Check") -> OK | H11: https://www.fortpro.com/semi-trucks-grilles
A12: Exterior Parts > Trucks Mirrors | B12: 2 | C12: Exterior Parts | D12: Trucks Mirrors | E12: 76 | F12: =SUMPRODUCT(--ISNUMBER(SEARCH("| "&A12,"| "&Products!$H$2:$H$3170))) -> 76 | G12: =IF(E12=F12,"OK","Check") -> OK | H12: https://www.fortpro.com/semi-trucks-mirrors
A13: Exterior Parts > Rear Panels | B13: 2 | C13: Exterior Parts | D13: Rear Panels | E13: 4 | F13: =SUMPRODUCT(--ISNUMBER(SEARCH("| "&A13,"| "&Products!$H$2:$H$3170))) -> 4 | G13: =IF(E13=F13,"OK","Check") -> OK | H13: https://www.fortpro.com/semi-trucks-rear-panels
... A186: Lucas Oil Products > Assembly & Workshop Products | B186: 2 | C186: Lucas Oil Products | D186: Assembly & Workshop Products | E186: 2 | F186: =SUMPRODUCT(--ISNUMBER(SEARCH("| "&A186,"| "&Products!$H$2:$H$3170))) -> 2 | G186: =IF(E186=F186,"OK","Check") -> OK | H186: https://www.fortpro.com/assembly-workshop-products
A188: Site Count is hardcoded from the crawl on Oct 10, 2026 (source: each category page on fortpro.com). Count in Record is a formula on the Products tab. Parent categories include all products in their subcategories.
